Workbook

Sheet Pivot Tables & Dashboards
O5: For each brand, how many products have a discount greater than 30%?
B6: Product count and average price by SUBCATEGORY and SUBSUBCATEGORY. | F6: How many products fall into each price band: €0–15, €15–30, €30–50, €50+?
O7: Brand | P7: Discount >30%
B8: Row Labels | C8: Average Price | D8: Product | O8: Adidas Performance | P8: 24
B9: Polo Shirts | C9: 19.602149 | D9: 498 | G9: Price Distribution | H9: Total Order | O9: Nike | P9: 17
B10: Basic Polos | C10: 20.142273 | D10: 154 | G10: 0–15 | H10: 438 | O10: Tommy Hilfiger | P10: 16
B11: Pique Polos | C11: 19.787616 | D11: 172 | G11: 15-30 | H11: 422 | O11: Lacoste | P11: 8
B12: Slim Fit Polos | C12: 18.933081 | D12: 172 | G12: 30-50 | H12: 103 | O12: Cars Jeans | P12: 8
B13: T-Shirts | C13: 18.610453 | D13: 486 | G13: >50 | H13: 103 | O13: Jack & Jones Junior | P13: 7
B14: Basic T-Shirts | C14: 17.934355 | D14: 124 | O14: Only & Sons | P14: 6
B15: Long Sleeve T-Shirts | C15: 19.650776 | D15: 116 | O15: Salomon | P15: 5
B16: Print T-Shirts | C16: 17.535259 | D16: 116 | O16: New Look | P16: 5
B17: Slim Fit T-Shirts | C17: 19.286462 | D17: 130 | O17: Produkt | P17: 5
B18: Grand Total | C18: 19.112348 | D18: 984 | O18: Anthracite | P18: 5
O19: Anerkjendt | P19: 5
O20: Fila | P20: 4
O21: Puma | P21: 4
O22: Element | P22: 4
O23: Boss | P23: 4
O24: Carhartt Wip | P24: 4
O25: Bershka | P25: 3
O26: Levi's | P26: 3
O27: Urban Classics | P27: 3
O28: Seidensticker | P28: 3
O29: Dickies | P29: 3
O30: Craft | P30: 3
... O142: Iriedaily | P142: 1

Sheet Product Lookup & Search
B2: SKU and return the product name, brand, and current price.
B4: Sku | C4: Product name | D4: Brand | E4: Current Price
B5: ZL100271 | C5: {=_xlfn.XLOOKUP(B5,Real_Sales[[#All],[Sku]],Real_Sales[[#All],[Product_name]])} -> Essential T-SHIRT - RED | D5: {=_xlfn.XLOOKUP('Product Lookup & Search'!B5,Real_Sales[[#All],[Sku]],Real_Sales[[#All],[Brand]])} -> Only & Sons | E5: {=_xlfn.XLOOKUP(B5,Real_Sales[[#All],[Sku]],Real_Sales[[#All],[Price_retail]])} -> 36.16
B6: ZL100216 | C6: {=_xlfn.XLOOKUP(B6,Real_Sales[[#All],[Sku]],Real_Sales[[#All],[Product_name]])} -> Print T-SHIRT - GREY MELANGE | D6: {=_xlfn.XLOOKUP('Product Lookup & Search'!B6,Real_Sales[[#All],[Sku]],Real_Sales[[#All],[Brand]])} -> Lacoste | E6: {=_xlfn.XLOOKUP(B6,Real_Sales[[#All],[Sku]],Real_Sales[[#All],[Price_retail]])} -> 8.99
B7: ZL100525 | C7: {=_xlfn.XLOOKUP(B7,Real_Sales[[#All],[Sku]],Real_Sales[[#All],[Product_name]])} -> Basic T-SHIRT - DENIM BLUE | D7: {=_xlfn.XLOOKUP('Product Lookup & Search'!B7,Real_Sales[[#All],[Sku]],Real_Sales[[#All],[Brand]])} -> Adidas Performance | E7: {=_xlfn.XLOOKUP(B7,Real_Sales[[#All],[Sku]],Real_Sales[[#All],[Price_retail]])} -> 8.99
B8: ZL100393 | C8: {=_xlfn.XLOOKUP(B8,Real_Sales[[#All],[Sku]],Real_Sales[[#All],[Product_name]])} -> Slim Fit T-SHIRT - BORDEAUX | D8: {=_xlfn.XLOOKUP('Product Lookup & Search'!B8,Real_Sales[[#All],[Sku]],Real_Sales[[#All],[Brand]])} -> Urban Classics | E8: {=_xlfn.XLOOKUP(B8,Real_Sales[[#All],[Sku]],Real_Sales[[#All],[Price_retail]])} -> 8.99
B9: ZL100303 | C9: {=_xlfn.XLOOKUP(B9,Real_Sales[[#All],[Sku]],Real_Sales[[#All],[Product_name]])} -> Essential POLO - BORDEAUX | D9: {=_xlfn.XLOOKUP('Product Lookup & Search'!B9,Real_Sales[[#All],[Sku]],Real_Sales[[#All],[Brand]])} -> Blend She | E9: {=_xlfn.XLOOKUP(B9,Real_Sales[[#All],[Sku]],Real_Sales[[#All],[Price_retail]])} -> 8.99
B10: ZL100738 | C10: {=_xlfn.XLOOKUP(B10,Real_Sales[[#All],[Sku]],Real_Sales[[#All],[Product_name]])} -> Slim Fit T-SHIRT - OLIVE | D10: {=_xlfn.XLOOKUP('Product Lookup & Search'!B10,Real_Sales[[#All],[Sku]],Real_Sales[[#All],[Brand]])} -> Seidensticker | E10: {=_xlfn.XLOOKUP(B10,Real_Sales[[#All],[Sku]],Real_Sales[[#All],[Price_retail]])} -> 8.99
B11: ZL100247 | C11: {=_xlfn.XLOOKUP(B11,Real_Sales[[#All],[Sku]],Real_Sales[[#All],[Product_name]])} -> Slim Fit T-SHIRT - MINT | D11: {=_xlfn.XLOOKUP('Product Lookup & Search'!B11,Real_Sales[[#All],[Sku]],Real_Sales[[#All],[Brand]])} -> Fila | E11: {=_xlfn.XLOOKUP(B11,Real_Sales[[#All],[Sku]],Real_Sales[[#All],[Price_retail]])} -> 8.99
B12: ZL100887 | C12: {=_xlfn.XLOOKUP(B12,Real_Sales[[#All],[Sku]],Real_Sales[[#All],[Product_name]])} -> Regular Fit T-SHIRT - DARK BLUE | D12: {=_xlfn.XLOOKUP('Product Lookup & Search'!B12,Real_Sales[[#All],[Sku]],Real_Sales[[#All],[Brand]])} -> Nike | E12: {=_xlfn.XLOOKUP(B12,Real_Sales[[#All],[Sku]],Real_Sales[[#All],[Price_retail]])} -> 10.71
B13: ZL100887 | C13: {=_xlfn.XLOOKUP(B13,Real_Sales[[#All],[Sku]],Real_Sales[[#All],[Product_name]])} -> Regular Fit T-SHIRT - DARK BLUE | D13: {=_xlfn.XLOOKUP('Product Lookup & Search'!B13,Real_Sales[[#All],[Sku]],Real_Sales[[#All],[Brand]])} -> Nike | E13: {=_xlfn.XLOOKUP(B13,Real_Sales[[#All],[Sku]],Real_Sales[[#All],[Price_retail]])} -> 10.71
B14: ZL100656 | C14: {=_xlfn.XLOOKUP(B14,Real_Sales[[#All],[Sku]],Real_Sales[[#All],[Product_name]])} -> Regular Fit T-SHIRT - DENIM BLUE | D14: {=_xlfn.XLOOKUP('Product Lookup & Search'!B14,Real_Sales[[#All],[Sku]],Real_Sales[[#All],[Brand]])} -> Denim & Supply | E14: {=_xlfn.XLOOKUP(B14,Real_Sales[[#All],[Sku]],Real_Sales[[#All],[Price_retail]])} -> 10.72

Sheet Pricing & Discount Analysis
B2: Count Discounted Products | E2: =COUNTIF(Real_Sales[Price_label],"Sale") -> 406
B5: What is the average, minimum, and maximum current price per brand?
B7: Row Labels | C7: Average Reteil Price | D7: Max Retail Price | E7: Min Retail Price | H7: Which 10 products have the largest absolute price drop ?
B8: Adidas Originals | C8: 11.3025 | D8: 13.82 | E8: 8.99
B9: Adidas Performance | C9: 20.888205 | D9: 85.77 | E9: 8.99 | H9: Brand | I9: Discount
B10: Alpha Industries | C10: 11.27 | D10: 13.55 | E10: 8.99 | H10: Produkt | I10: 0.70020747
B11: Anerkjendt | C11: 21.293 | D11: 38.33 | E11: 8.99 | H11: Zign | I11: 0.70007987
B12: Anthracite | C12: 18.758 | D12: 28.26 | E12: 8.99 | H12: Selected Homme | I12: 0.62836723
B13: Anti Fashion | C13: 19.099 | D13: 32.12 | E13: 8.99 | H13: Denim & Supply | I13: 0.60552017
B14: Armani Exchange | C14: 10.3 | D14: 11.61 | E14: 8.99 | H14: Lacoste | I14: 0.59798842
B15: Baldessarini | C15: 24.445 | D15: 35.22 | E15: 13.67 | H15: Mango Man | I15: 0.5850682
B16: Barbour | C16: 15.725 | D16: 20.64 | E16: 10.81 | H16: Produkt | I16: 0.58324382
B17: Ben Sherman | C17: 24.793333 | D17: 37.35 | E17: 15.41 | H17: Adidas Performance | I17: 0.5810093
B18: Bershka | C18: 17.995 | D18: 26.41 | E18: 8.99 | H18: Petrol Industries | I18: 0.57685769
B19: Billabong | C19: 13.92 | D19: 18.85 | E19: 8.99 | H19: Tommy Hilfiger | I19: 0.57616417
B20: Björn Borg | C20: 18.184286 | D20: 26.73 | E20: 10.62
B21: Blend | C21: 14.01 | D21: 14.01 | E21: 14.01
B22: Blend She | C22: 11.71 | D22: 19.3 | E22: 6.99
B23: Boss | C23: 15.667143 | D23: 20.77 | E23: 9.09
B24: Boss Orange | C24: 10.155 | D24: 11.32 | E24: 8.99
B25: Brixton | C25: 17.723333 | D25: 32.42 | E25: 8.99
B26: Bruuns Bazaar | C26: 20.288 | D26: 41.51 | E26: 12.12
B27: Burton Menswear London | C27: 18.641429 | D27: 34.62 | E27: 9.67
B28: Calvin Klein | C28: 16.9665 | D28: 37.38 | E28: 8.99
B29: Carhartt Wip | C29: 17.798 | D29: 33.57 | E29: 9.41
B30: Cars Jeans | C30: 20.936087 | D30: 53.93 | E30: 8.99
B31: Casual Friday | C31: 12.89 | D31: 15.19 | E31: 11.31
... B143: Grand Total | C143: 19.119528 | D143: 99.99 | E143: 6.99

Sheet Brand
B2: What is the total revenue potential per brand?
B3: How many products does each brand have listed? Which brand has the most SKUs?
C5: Number Of Product | D5: Percentage of Product | E5: Number of Sku | F5: Revenue
B6: Nike | C6: 100 | D6: 0.10162602 | E6: 100 | F6: 1750.43
B7: Adidas Performance | C7: 75 | D7: 0.076219512 | E7: 75 | F7: 1356.9
B8: Tommy Hilfiger | C8: 62 | D8: 0.06300813 | E8: 62 | F8: 1012.11 | M8: Brand | N8: Number of Products
B9: Only & Sons | C9: 27 | D9: 0.027439024 | E9: 27 | F9: 476.51 | M9: =B6 -> Nike | N9: =C6 -> 100
B10: Cars Jeans | C10: 23 | D10: 0.023373984 | E10: 23 | F10: 402.99 | M10: =B7 -> Adidas Performance | N10: =C7 -> 75
B11: Calvin Klein | C11: 20 | D11: 0.020325203 | E11: 20 | F11: 320.57 | M11: =B8 -> Tommy Hilfiger | N11: =C8 -> 62
B12: Produkt | C12: 20 | D12: 0.020325203 | E12: 20 | F12: 298.39 | M12: =B9 -> Only & Sons | N12: =C9 -> 27
B13: Anerkjendt | C13: 20 | D13: 0.020325203 | E13: 20 | F13: 372.72 | M13: =B10 -> Cars Jeans | N13: =C10 -> 23
B14: Salomon | C14: 18 | D14: 0.018292683 | E14: 18 | F14: 238.91 | M14: =B11 -> Calvin Klein | N14: =C11 -> 20
B15: Jack & Jones Junior | C15: 18 | D15: 0.018292683 | E15: 18 | F15: 309.6 | M15: =B12 -> Produkt | N15: =C12 -> 20
B16: Lacoste | C16: 17 | D16: 0.017276423 | E16: 17 | F16: 207.52 | M16: =B13 -> Anerkjendt | N16: =C13 -> 20
B17: Puma | C17: 16 | D17: 0.016260163 | E17: 16 | F17: 350.4 | M17: =B14 -> Salomon | N17: =C14 -> 18
B18: Guess | C18: 15 | D18: 0.015243902 | E18: 15 | F18: 201.09 | M18: =B15 -> Jack & Jones Junior | N18: =C15 -> 18
B19: Fila | C19: 14 | D19: 0.014227642 | E19: 14 | F19: 181.31
B20: Burton Menswear London | C20: 13 | D20: 0.013211382 | E20: 13 | F20: 213.4
B21: Mango Man | C21: 12 | D21: 0.012195122 | E21: 12 | F21: 139.34
B22: Element | C22: 12 | D22: 0.012195122 | E22: 12 | F22: 199.79
B23: Pier One | C23: 12 | D23: 0.012195122 | E23: 12 | F23: 203.83
B24: Shine Original | C24: 12 | D24: 0.012195122 | E24: 12 | F24: 216.01
B25: Anthracite | C25: 10 | D25: 0.010162602 | E25: 10 | F25: 157.14
B26: New Look | C26: 10 | D26: 0.010162602 | E26: 10 | F26: 121.51
B27: Levi's | C27: 10 | D27: 0.010162602 | E27: 10 | F27: 161.88
B28: J.Lindeberg | C28: 10 | D28: 0.010162602 | E28: 10 | F28: 129.16
B29: Craft | C29: 9 | D29: 0.0091463415 | E29: 9 | F29: 101.59
B30: Seidensticker | C30: 9 | D30: 0.0091463415 | E30: 9 | F30: 125.32
... B141: Grand Total | C141: 984 | D141: 1 | E141: 984 | F141: 16235.6

Sheet Real Sale
A1: Sku | B1: Product_url | C1: Brand | D1: Product_name | E1: Category | F1: Subcategory | G1: Subsubcategory | H1: Color | I1: Size_range | J1: Price_retail | K1: Price_current | L1: Price_label | M1: Currency | N1: Sort_by_ranking | O1: Rating | P1: Reviews_count | Q1: Promotion | R1: Sku_variant | S1: In_stock | T1: Scan_date | U1: Image_url | V1: Discount | W1: Discount Level | X1: Column1 | Y1: Basic Procut Name | Z1: Price range
A2: ZL100041 | B2: https://www.zalando.de/blend-she-essential-t-shirt---bordeaux-zl100041/ | C2: Blend She | D2: Essential T-SHIRT - BORDEAUX | E2: Men's T-Shirts & Polos | F2: T-Shirts | G2: Print T-Shirts | H2: Bordeaux | I2: XS | J2: 6.99 | K2: 6.99 | L2: NEW | M2: EUR | N2: 355 | O2: 3.2 | P2: 35.0 | S2: No | T2: 44955 | U2: https://img01.ztat.net/article/ZL100041.jpg | V2: =(Real_Sales[[#This Row],[Price_retail]]-Real_Sales[[#This Row],[Price_current]])/Real_Sales[[#This Row],[Price_retail]] -> 0 | W2: {=_xlfn.IFS(Real_Sales[[#This Row],[Discount]]=0%,"No Discount",Real_Sales[[#This Row],[Discount]]<=20%,"Light",Real_Sales[[#This Row],[Discount]]<=50%,"Moderate",Real_Sales[[#This Row],[Discount]]<=80%,"High", TRUE,"Very High")} -> No Discount | X2: =IF(Real_Sales[[#This Row],[Price_retail]]>$AC$3,"Premium","Average") -> Average | Y2: =IF(ISNUMBER(SEARCH("Basic",Real_Sales[[#This Row],[Product_name]])),"Yes","No") -> No | Z2: {=_xlfn.IFS(Real_Sales[[#This Row],[Price_retail]]<=15,1, Real_Sales[[#This Row],[Price_retail]]<=30,2, Real_Sales[[#This Row],[Price_retail]]<=50,3,Real_Sales[[#This Row],[Price_retail]]>50,4)} -> 1 | AC2: Average retail price
A3: ZL100359 | B3: https://www.zalando.de/columbia-print-t-shirt---white-zl100359/ | C3: Columbia | D3: Print T-SHIRT - WHITE | E3: Men's T-Shirts & Polos | F3: T-Shirts | G3: Slim Fit T-Shirts | H3: White | I3: S | J3: 8.99 | K3: 3.99 | L3: SALE | M3: EUR | N3: 892 | O3: 3.7 | P3: 42.0 | S3: Yes | T3: 44955 | U3: https://img01.ztat.net/article/ZL100359.jpg | V3: =(Real_Sales[[#This Row],[Price_retail]]-Real_Sales[[#This Row],[Price_current]])/Real_Sales[[#This Row],[Price_retail]] -> 0.55617353 | W3: {=_xlfn.IFS(Real_Sales[[#This Row],[Discount]]=0%,"No Discount",Real_Sales[[#This Row],[Discount]]<=20%,"Light",Real_Sales[[#This Row],[Discount]]<=50%,"Moderate",Real_Sales[[#This Row],[Discount]]<=80%,"High", TRUE,"Very High")} -> High | X3: =IF(Real_Sales[[#This Row],[Price_retail]]>$AC$3,"Premium","Average") -> Average | Y3: =IF(ISNUMBER(SEARCH("Basic",Real_Sales[[#This Row],[Product_name]])),"Yes","No") -> No | Z3: {=_xlfn.IFS(Real_Sales[[#This Row],[Price_retail]]<=15,1, Real_Sales[[#This Row],[Price_retail]]<=30,2, Real_Sales[[#This Row],[Price_retail]]<=50,3,Real_Sales[[#This Row],[Price_retail]]>50,4)} -> 1 | AC3: =AVERAGEA(Real_Sales[Price_retail]) -> 19.112348
A4: ZL100440 | B4: https://www.zalando.de/tommy-hilfiger-basic-polo---dark-blue-zl100440/ | C4: Tommy Hilfiger | D4: Basic POLO - DARK BLUE | E4: Men's T-Shirts & Polos | F4: Polo Shirts | G4: Slim Fit Polos | H4: Dark Blue | I4: XS | J4: 8.99 | K4: 3.99 | L4: SALE | M4: EUR | N4: 362 | O4: 3.6 | P4: 37.0 | S4: Yes | T4: 44955 | U4: https://img01.ztat.net/article/ZL100440.jpg | V4: =(Real_Sales[[#This Row],[Price_retail]]-Real_Sales[[#This Row],[Price_current]])/Real_Sales[[#This Row],[Price_retail]] -> 0.55617353 | W4: {=_xlfn.IFS(Real_Sales[[#This Row],[Discount]]=0%,"No Discount",Real_Sales[[#This Row],[Discount]]<=20%,"Light",Real_Sales[[#This Row],[Discount]]<=50%,"Moderate",Real_Sales[[#This Row],[Discount]]<=80%,"High", TRUE,"Very High")} -> High | X4: =IF(Real_Sales[[#This Row],[Price_retail]]>$AC$3,"Premium","Average") -> Average | Y4: =IF(ISNUMBER(SEARCH("Basic",Real_Sales[[#This Row],[Product_name]])),"Yes","No") -> Yes | Z4: {=_xlfn.IFS(Real_Sales[[#This Row],[Price_retail]]<=15,1, Real_Sales[[#This Row],[Price_retail]]<=30,2, Real_Sales[[#This Row],[Price_retail]]<=50,3,Real_Sales[[#This Row],[Price_retail]]>50,4)} -> 1
A5: ZL100672 | B5: https://www.zalando.de/bershka-slim-fit-t-shirt---royal-blue-zl100672/ | C5: Bershka | D5: Slim Fit T-SHIRT - ROYAL BLUE | E5: Men's T-Shirts & Polos | F5: T-Shirts | G5: Slim Fit T-Shirts | H5: Royal Blue | I5: XS | J5: 8.99 | K5: 3.99 | L5: SALE | M5: EUR | N5: 197 | O5: 3.2 | P5: 39.0 | S5: Yes | T5: 44955 | U5: https://img01.ztat.net/article/ZL100672.jpg | V5: =(Real_Sales[[#This Row],[Price_retail]]-Real_Sales[[#This Row],[Price_current]])/Real_Sales[[#This Row],[Price_retail]] -> 0.55617353 | W5: {=_xlfn.IFS(Real_Sales[[#This Row],[Discount]]=0%,"No Discount",Real_Sales[[#This Row],[Discount]]<=20%,"Light",Real_Sales[[#This Row],[Discount]]<=50%,"Moderate",Real_Sales[[#This Row],[Discount]]<=80%,"High", TRUE,"Very High")} -> High | X5: =IF(Real_Sales[[#This Row],[Price_retail]]>$AC$3,"Premium","Average") -> Average | Y5: =IF(ISNUMBER(SEARCH("Basic",Real_Sales[[#This Row],[Product_name]])),"Yes","No") -> No | Z5: {=_xlfn.IFS(Real_Sales[[#This Row],[Price_retail]]<=15,1, Real_Sales[[#This Row],[Price_retail]]<=30,2, Real_Sales[[#This Row],[Price_retail]]<=50,3,Real_Sales[[#This Row],[Price_retail]]>50,4)} -> 1
A6: ZL100726 | B6: https://www.zalando.de/calvin-klein-basic-polo---khaki-zl100726/ | C6: Calvin Klein | D6: Basic POLO - KHAKI | E6: Men's T-Shirts & Polos | F6: Polo Shirts | G6: Basic Polos | H6: Khaki | I6: S | J6: 8.99 | K6: 3.99 | L6: SALE | M6: EUR | N6: 339 | O6: 0 | P6: 27.0 | S6: Yes | T6: 44955 | U6: https://img01.ztat.net/article/ZL100726.jpg | V6: =(Real_Sales[[#This Row],[Price_retail]]-Real_Sales[[#This Row],[Price_current]])/Real_Sales[[#This Row],[Price_retail]] -> 0.55617353 | W6: {=_xlfn.IFS(Real_Sales[[#This Row],[Discount]]=0%,"No Discount",Real_Sales[[#This Row],[Discount]]<=20%,"Light",Real_Sales[[#This Row],[Discount]]<=50%,"Moderate",Real_Sales[[#This Row],[Discount]]<=80%,"High", TRUE,"Very High")} -> High | X6: =IF(Real_Sales[[#This Row],[Price_retail]]>$AC$3,"Premium","Average") -> Average | Y6: =IF(ISNUMBER(SEARCH("Basic",Real_Sales[[#This Row],[Product_name]])),"Yes","No") -> Yes | Z6: {=_xlfn.IFS(Real_Sales[[#This Row],[Price_retail]]<=15,1, Real_Sales[[#This Row],[Price_retail]]<=30,2, Real_Sales[[#This Row],[Price_retail]]<=50,3,Real_Sales[[#This Row],[Price_retail]]>50,4)} -> 1
A7: ZL100873 | B7: https://www.zalando.de/timberland-pro-print-polo---red-zl100873/ | C7: Timberland Pro | D7: Print POLO - RED | E7: Men's T-Shirts & Polos | F7: Polo Shirts | G7: Pique Polos | H7: Red | I7: S | J7: 8.99 | K7: 4.04 | L7: SALE | M7: EUR | N7: 280 | O7: 4.6 | P7: 0 | S7: Yes | T7: 44955 | U7: https://img01.ztat.net/article/ZL100873.jpg | V7: =(Real_Sales[[#This Row],[Price_retail]]-Real_Sales[[#This Row],[Price_current]])/Real_Sales[[#This Row],[Price_retail]] -> 0.55061179 | W7: {=_xlfn.IFS(Real_Sales[[#This Row],[Discount]]=0%,"No Discount",Real_Sales[[#This Row],[Discount]]<=20%,"Light",Real_Sales[[#This Row],[Discount]]<=50%,"Moderate",Real_Sales[[#This Row],[Discount]]<=80%,"High", TRUE,"Very High")} -> High | X7: =IF(Real_Sales[[#This Row],[Price_retail]]>$AC$3,"Premium","Average") -> Average | Y7: =IF(ISNUMBER(SEARCH("Basic",Real_Sales[[#This Row],[Product_name]])),"Yes","No") -> No | Z7: {=_xlfn.IFS(Real_Sales[[#This Row],[Price_retail]]<=15,1, Real_Sales[[#This Row],[Price_retail]]<=30,2, Real_Sales[[#This Row],[Price_retail]]<=50,3,Real_Sales[[#This Row],[Price_retail]]>50,4)} -> 1
A8: ZL100421 | B8: https://www.zalando.de/adidas-performance-slim-fit-polo---olive-zl100421/ | C8: Adidas Performance | D8: Slim Fit POLO - OLIVE | E8: Men's T-Shirts & Polos | F8: Polo Shirts | G8: Slim Fit Polos | H8: Olive | I8: S | J8: 8.99 | K8: 4.23 | L8: SALE | M8: EUR | N8: 590 | O8: 3.3 | P8: 42.0 | S8: Yes | T8: 44955 | U8: https://img01.ztat.net/article/ZL100421.jpg | V8: =(Real_Sales[[#This Row],[Price_retail]]-Real_Sales[[#This Row],[Price_current]])/Real_Sales[[#This Row],[Price_retail]] -> 0.5294772 | W8: {=_xlfn.IFS(Real_Sales[[#This Row],[Discount]]=0%,"No Discount",Real_Sales[[#This Row],[Discount]]<=20%,"Light",Real_Sales[[#This Row],[Discount]]<=50%,"Moderate",Real_Sales[[#This Row],[Discount]]<=80%,"High", TRUE,"Very High")} -> High | X8: =IF(Real_Sales[[#This Row],[Price_retail]]>$AC$3,"Premium","Average") -> Average | Y8: =IF(ISNUMBER(SEARCH("Basic",Real_Sales[[#This Row],[Product_name]])),"Yes","No") -> No | Z8: {=_xlfn.IFS(Real_Sales[[#This Row],[Price_retail]]<=15,1, Real_Sales[[#This Row],[Price_retail]]<=30,2, Real_Sales[[#This Row],[Price_retail]]<=50,3,Real_Sales[[#This Row],[Price_retail]]>50,4)} -> 1
A9: ZL100236 | B9: https://www.zalando.de/the-north-face-regular-fit-polo---navy-zl100236/ | C9: The North Face | D9: Regular Fit POLO - NAVY | E9: Men's T-Shirts & Polos | F9: Polo Shirts | G9: Slim Fit Polos | H9: Navy | I9: M | J9: 8.99 | K9: 4.34 | L9: SALE | M9: EUR | N9: 871 | O9: 4.1 | P9: 32.0 | S9: Yes | T9: 44955 | U9: https://img01.ztat.net/article/ZL100236.jpg | V9: =(Real_Sales[[#This Row],[Price_retail]]-Real_Sales[[#This Row],[Price_current]])/Real_Sales[[#This Row],[Price_retail]] -> 0.51724138 | W9: {=_xlfn.IFS(Real_Sales[[#This Row],[Discount]]=0%,"No Discount",Real_Sales[[#This Row],[Discount]]<=20%,"Light",Real_Sales[[#This Row],[Discount]]<=50%,"Moderate",Real_Sales[[#This Row],[Discount]]<=80%,"High", TRUE,"Very High")} -> High | X9: =IF(Real_Sales[[#This Row],[Price_retail]]>$AC$3,"Premium","Average") -> Average | Y9: =IF(ISNUMBER(SEARCH("Basic",Real_Sales[[#This Row],[Product_name]])),"Yes","No") -> No | Z9: {=_xlfn.IFS(Real_Sales[[#This Row],[Price_retail]]<=15,1, Real_Sales[[#This Row],[Price_retail]]<=30,2, Real_Sales[[#This Row],[Price_retail]]<=50,3,Real_Sales[[#This Row],[Price_retail]]>50,4)} -> 1
A10: ZL100524 | B10: https://www.zalando.de/nn07-basic-polo---royal-blue-zl100524/ | C10: Nike | D10: Basic POLO - ROYAL BLUE | E10: Men's T-Shirts & Polos | F10: Polo Shirts | G10: Slim Fit Polos | H10: Royal Blue | I10: XS | J10: 8.99 | K10: 4.48 | L10: SALE | M10: EUR | N10: 798 | O10: 4.1 | P10: 30.0 | T10: 44955 | U10: https://img01.ztat.net/article/ZL100524.jpg | V10: =(Real_Sales[[#This Row],[Price_retail]]-Real_Sales[[#This Row],[Price_current]])/Real_Sales[[#This Row],[Price_retail]] -> 0.50166852 | W10: {=_xlfn.IFS(Real_Sales[[#This Row],[Discount]]=0%,"No Discount",Real_Sales[[#This Row],[Discount]]<=20%,"Light",Real_Sales[[#This Row],[Discount]]<=50%,"Moderate",Real_Sales[[#This Row],[Discount]]<=80%,"High", TRUE,"Very High")} -> High | X10: =IF(Real_Sales[[#This Row],[Price_retail]]>$AC$3,"Premium","Average") -> Average | Y10: =IF(ISNUMBER(SEARCH("Basic",Real_Sales[[#This Row],[Product_name]])),"Yes","No") -> Yes | Z10: {=_xlfn.IFS(Real_Sales[[#This Row],[Price_retail]]<=15,1, Real_Sales[[#This Row],[Price_retail]]<=30,2, Real_Sales[[#This Row],[Price_retail]]<=50,3,Real_Sales[[#This Row],[Price_retail]]>50,4)} -> 1
A11: ZL100144 | B11: https://www.zalando.de/levi's-essential-polo---navy-zl100144/ | C11: Levi's | D11: Essential POLO - NAVY | E11: Men's T-Shirts & Polos | F11: Polo Shirts | G11: Pique Polos | H11: Navy | I11: S | J11: 8.99 | K11: 4.59 | L11: SALE | M11: EUR | N11: 267 | O11: 4.7 | P11: 46.0 | S11: Yes | T11: 44955 | U11: https://img01.ztat.net/article/ZL100144.jpg | V11: =(Real_Sales[[#This Row],[Price_retail]]-Real_Sales[[#This Row],[Price_current]])/Real_Sales[[#This Row],[Price_retail]] -> 0.4894327 | W11: {=_xlfn.IFS(Real_Sales[[#This Row],[Discount]]=0%,"No Discount",Real_Sales[[#This Row],[Discount]]<=20%,"Light",Real_Sales[[#This Row],[Discount]]<=50%,"Moderate",Real_Sales[[#This Row],[Discount]]<=80%,"High", TRUE,"Very High")} -> Moderate | X11: =IF(Real_Sales[[#This Row],[Price_retail]]>$AC$3,"Premium","Average") -> Average | Y11: =IF(ISNUMBER(SEARCH("Basic",Real_Sales[[#This Row],[Product_name]])),"Yes","No") -> No | Z11: {=_xlfn.IFS(Real_Sales[[#This Row],[Price_retail]]<=15,1, Real_Sales[[#This Row],[Price_retail]]<=30,2, Real_Sales[[#This Row],[Price_retail]]<=50,3,Real_Sales[[#This Row],[Price_retail]]>50,4)} -> 1
A12: ZL100216 | B12: https://www.zalando.de/lacoste-print-t-shirt---grey-melange-zl100216/ | C12: Lacoste | D12: Print T-SHIRT - GREY MELANGE | E12: Men's T-Shirts & Polos | F12: T-Shirts | G12: Basic T-Shirts | H12: Grey Melange | I12: XS | J12: 8.99 | K12: 4.59 | L12: SALE | M12: EUR | N12: 779 | O12: 0 | P12: 33.0 | S12: No | T12: 44955 | U12: https://img01.ztat.net/article/ZL100216.jpg | V12: =(Real_Sales[[#This Row],[Price_retail]]-Real_Sales[[#This Row],[Price_current]])/Real_Sales[[#This Row],[Price_retail]] -> 0.4894327 | W12: {=_xlfn.IFS(Real_Sales[[#This Row],[Discount]]=0%,"No Discount",Real_Sales[[#This Row],[Discount]]<=20%,"Light",Real_Sales[[#This Row],[Discount]]<=50%,"Moderate",Real_Sales[[#This Row],[Discount]]<=80%,"High", TRUE,"Very High")} -> Moderate | X12: =IF(Real_Sales[[#This Row],[Price_retail]]>$AC$3,"Premium","Average") -> Average | Y12: =IF(ISNUMBER(SEARCH("Basic",Real_Sales[[#This Row],[Product_name]])),"Yes","No") -> No | Z12: {=_xlfn.IFS(Real_Sales[[#This Row],[Price_retail]]<=15,1, Real_Sales[[#This Row],[Price_retail]]<=30,2, Real_Sales[[#This Row],[Price_retail]]<=50,3,Real_Sales[[#This Row],[Price_retail]]>50,4)} -> 1
A13: ZL100525 | B13: https://www.zalando.de/adidas-performance-basic-t-shirt---denim-blue-zl100525/ | C13: Adidas Performance | D13: Basic T-SHIRT - DENIM BLUE | E13: Men's T-Shirts & Polos | F13: T-Shirts | G13: Slim Fit T-Shirts | H13: Denim Blue | I13: S | J13: 8.99 | K13: 4.61 | L13: SALE | M13: EUR | N13: 780 | O13: 4.7 | P13: 36.0 | S13: Yes | T13: 44955 | U13: https://img01.ztat.net/article/ZL100525.jpg | V13: =(Real_Sales[[#This Row],[Price_retail]]-Real_Sales[[#This Row],[Price_current]])/Real_Sales[[#This Row],[Price_retail]] -> 0.48720801 | W13: {=_xlfn.IFS(Real_Sales[[#This Row],[Discount]]=0%,"No Discount",Real_Sales[[#This Row],[Discount]]<=20%,"Light",Real_Sales[[#This Row],[Discount]]<=50%,"Moderate",Real_Sales[[#This Row],[Discount]]<=80%,"High", TRUE,"Very High")} -> Moderate | X13: =IF(Real_Sales[[#This Row],[Price_retail]]>$AC$3,"Premium","Average") -> Average | Y13: =IF(ISNUMBER(SEARCH("Basic",Real_Sales[[#This Row],[Product_name]])),"Yes","No") -> Yes | Z13: {=_xlfn.IFS(Real_Sales[[#This Row],[Price_retail]]<=15,1, Real_Sales[[#This Row],[Price_retail]]<=30,2, Real_Sales[[#This Row],[Price_retail]]<=50,3,Real_Sales[[#This Row],[Price_retail]]>50,4)} -> 1
A14: ZL100393 | B14: https://www.zalando.de/urban-classics-slim-fit-t-shirt---bordeaux-zl100393/ | C14: Urban Classics | D14: Slim Fit T-SHIRT - BORDEAUX | E14: Men's T-Shirts & Polos | F14: T-Shirts | G14: Print T-Shirts | H14: Bordeaux | I14: M | J14: 8.99 | K14: 4.66 | L14: SALE | M14: EUR | N14: 235 | O14: 0 | P14: 30.0 | S14: Yes | T14: 44955 | U14: https://img01.ztat.net/article/ZL100393.jpg | V14: =(Real_Sales[[#This Row],[Price_retail]]-Real_Sales[[#This Row],[Price_current]])/Real_Sales[[#This Row],[Price_retail]] -> 0.48164627 | W14: {=_xlfn.IFS(Real_Sales[[#This Row],[Discount]]=0%,"No Discount",Real_Sales[[#This Row],[Discount]]<=20%,"Light",Real_Sales[[#This Row],[Discount]]<=50%,"Moderate",Real_Sales[[#This Row],[Discount]]<=80%,"High", TRUE,"Very High")} -> Moderate | X14: =IF(Real_Sales[[#This Row],[Price_retail]]>$AC$3,"Premium","Average") -> Average | Y14: =IF(ISNUMBER(SEARCH("Basic",Real_Sales[[#This Row],[Product_name]])),"Yes","No") -> No | Z14: {=_xlfn.IFS(Real_Sales[[#This Row],[Price_retail]]<=15,1, Real_Sales[[#This Row],[Price_retail]]<=30,2, Real_Sales[[#This Row],[Price_retail]]<=50,3,Real_Sales[[#This Row],[Price_retail]]>50,4)} -> 1
A15: ZL100303 | B15: https://www.zalando.de/blend-she-essential-polo---bordeaux-zl100303/ | C15: Blend She | D15: Essential POLO - BORDEAUX | E15: Men's T-Shirts & Polos | F15: Polo Shirts | G15: Basic Polos | H15: Bordeaux | I15: XS | J15: 8.99 | K15: 4.7 | L15: SALE | M15: EUR | N15: 957 | O15: 4.8 | P15: 24.0 | S15: Yes | T15: 44955 | U15: https://img01.ztat.net/article/ZL100303.jpg | V15: =(Real_Sales[[#This Row],[Price_retail]]-Real_Sales[[#This Row],[Price_current]])/Real_Sales[[#This Row],[Price_retail]] -> 0.47719689 | W15: {=_xlfn.IFS(Real_Sales[[#This Row],[Discount]]=0%,"No Discount",Real_Sales[[#This Row],[Discount]]<=20%,"Light",Real_Sales[[#This Row],[Discount]]<=50%,"Moderate",Real_Sales[[#This Row],[Discount]]<=80%,"High", TRUE,"Very High")} -> Moderate | X15: =IF(Real_Sales[[#This Row],[Price_retail]]>$AC$3,"Premium","Average") -> Average | Y15: =IF(ISNUMBER(SEARCH("Basic",Real_Sales[[#This Row],[Product_name]])),"Yes","No") -> No | Z15: {=_xlfn.IFS(Real_Sales[[#This Row],[Price_retail]]<=15,1, Real_Sales[[#This Row],[Price_retail]]<=30,2, Real_Sales[[#This Row],[Price_retail]]<=50,3,Real_Sales[[#This Row],[Price_retail]]>50,4)} -> 1
A16: ZL100738 | B16: https://www.zalando.de/seidensticker-slim-fit-t-shirt---olive-zl100738/ | C16: Seidensticker | D16: Slim Fit T-SHIRT - OLIVE | E16: Men's T-Shirts & Polos | F16: T-Shirts | G16: Basic T-Shirts | H16: Olive | I16: XS | J16: 8.99 | K16: 4.82 | L16: SALE | M16: EUR | N16: 452 | O16: 4.9 | P16: 47.0 | S16: Yes | T16: 44955 | U16: https://img01.ztat.net/article/ZL100738.jpg | V16: =(Real_Sales[[#This Row],[Price_retail]]-Real_Sales[[#This Row],[Price_current]])/Real_Sales[[#This Row],[Price_retail]] -> 0.46384872 | W16: {=_xlfn.IFS(Real_Sales[[#This Row],[Discount]]=0%,"No Discount",Real_Sales[[#This Row],[Discount]]<=20%,"Light",Real_Sales[[#This Row],[Discount]]<=50%,"Moderate",Real_Sales[[#This Row],[Discount]]<=80%,"High", TRUE,"Very High")} -> Moderate | X16: =IF(Real_Sales[[#This Row],[Price_retail]]>$AC$3,"Premium","Average") -> Average | Y16: =IF(ISNUMBER(SEARCH("Basic",Real_Sales[[#This Row],[Product_name]])),"Yes","No") -> No | Z16: {=_xlfn.IFS(Real_Sales[[#This Row],[Price_retail]]<=15,1, Real_Sales[[#This Row],[Price_retail]]<=30,2, Real_Sales[[#This Row],[Price_retail]]<=50,3,Real_Sales[[#This Row],[Price_retail]]>50,4)} -> 1
A17: ZL100247 | B17: https://www.zalando.de/fila-slim-fit-t-shirt---mint-zl100247/ | C17: Fila | D17: Slim Fit T-SHIRT - MINT | E17: Men's T-Shirts & Polos | F17: T-Shirts | G17: Basic T-Shirts | H17: Mint | I17: S | J17: 8.99 | K17: 4.89 | L17: SALE | M17: EUR | N17: 478 | O17: 3.8 | P17: 38.0 | S17: No | T17: 44955 | U17: https://img01.ztat.net/article/ZL100247.jpg | V17: =(Real_Sales[[#This Row],[Price_retail]]-Real_Sales[[#This Row],[Price_current]])/Real_Sales[[#This Row],[Price_retail]] -> 0.45606229 | W17: {=_xlfn.IFS(Real_Sales[[#This Row],[Discount]]=0%,"No Discount",Real_Sales[[#This Row],[Discount]]<=20%,"Light",Real_Sales[[#This Row],[Discount]]<=50%,"Moderate",Real_Sales[[#This Row],[Discount]]<=80%,"High", TRUE,"Very High")} -> Moderate | X17: =IF(Real_Sales[[#This Row],[Price_retail]]>$AC$3,"Premium","Average") -> Average | Y17: =IF(ISNUMBER(SEARCH("Basic",Real_Sales[[#This Row],[Product_name]])),"Yes","No") -> No | Z17: {=_xlfn.IFS(Real_Sales[[#This Row],[Price_retail]]<=15,1, Real_Sales[[#This Row],[Price_retail]]<=30,2, Real_Sales[[#This Row],[Price_retail]]<=50,3,Real_Sales[[#This Row],[Price_retail]]>50,4)} -> 1
A18: ZL100823 | B18: https://www.zalando.de/puma-print-t-shirt---grey-melange-zl100823/ | C18: Puma | D18: Print T-SHIRT - GREY MELANGE | E18: Men's T-Shirts & Polos | F18: T-Shirts | G18: Slim Fit T-Shirts | H18: Grey Melange | I18: M | J18: 8.99 | K18: 5.04 | L18: SALE | M18: EUR | N18: 702 | O18: 0 | P18: 31.0 | S18: Yes | T18: 44955 | U18: https://img01.ztat.net/article/ZL100823.jpg | V18: =(Real_Sales[[#This Row],[Price_retail]]-Real_Sales[[#This Row],[Price_current]])/Real_Sales[[#This Row],[Price_retail]] -> 0.43937709 | W18: {=_xlfn.IFS(Real_Sales[[#This Row],[Discount]]=0%,"No Discount",Real_Sales[[#This Row],[Discount]]<=20%,"Light",Real_Sales[[#This Row],[Discount]]<=50%,"Moderate",Real_Sales[[#This Row],[Discount]]<=80%,"High", TRUE,"Very High")} -> Moderate | X18: =IF(Real_Sales[[#This Row],[Price_retail]]>$AC$3,"Premium","Average") -> Average | Y18: =IF(ISNUMBER(SEARCH("Basic",Real_Sales[[#This Row],[Product_name]])),"Yes","No") -> No | Z18: {=_xlfn.IFS(Real_Sales[[#This Row],[Price_retail]]<=15,1, Real_Sales[[#This Row],[Price_retail]]<=30,2, Real_Sales[[#This Row],[Price_retail]]<=50,3,Real_Sales[[#This Row],[Price_retail]]>50,4)} -> 1
A19: ZL100407 | B19: https://www.zalando.de/adidas-performance-print-t-shirt---off-white-zl100407/ | C19: Adidas Performance | D19: Print T-SHIRT - OFF WHITE | E19: Men's T-Shirts & Polos | F19: T-Shirts | G19: Print T-Shirts | I19: S | J19: 8.99 | K19: 5.1 | L19: SALE | M19: EUR | N19: 45 | O19: 4.6 | P19: 40.0 | S19: Yes | T19: 44955 | U19: https://img01.ztat.net/article/ZL100407.jpg | V19: =(Real_Sales[[#This Row],[Price_retail]]-Real_Sales[[#This Row],[Price_current]])/Real_Sales[[#This Row],[Price_retail]] -> 0.432703 | W19: {=_xlfn.IFS(Real_Sales[[#This Row],[Discount]]=0%,"No Discount",Real_Sales[[#This Row],[Discount]]<=20%,"Light",Real_Sales[[#This Row],[Discount]]<=50%,"Moderate",Real_Sales[[#This Row],[Discount]]<=80%,"High", TRUE,"Very High")} -> Moderate | X19: =IF(Real_Sales[[#This Row],[Price_retail]]>$AC$3,"Premium","Average") -> Average | Y19: =IF(ISNUMBER(SEARCH("Basic",Real_Sales[[#This Row],[Product_name]])),"Yes","No") -> No | Z19: {=_xlfn.IFS(Real_Sales[[#This Row],[Price_retail]]<=15,1, Real_Sales[[#This Row],[Price_retail]]<=30,2, Real_Sales[[#This Row],[Price_retail]]<=50,3,Real_Sales[[#This Row],[Price_retail]]>50,4)} -> 1
A20: ZL100924 | B20: https://www.zalando.de/element-essential-t-shirt---light-grey-zl100924/ | C20: Element | D20: Essential T-SHIRT - LIGHT GREY | E20: Men's T-Shirts & Polos | F20: T-Shirts | G20: Long Sleeve T-Shirts | H20: Light Grey | I20: M | J20: 8.99 | K20: 5.12 | L20: SALE | M20: EUR | N20: 890 | O20: 0 | P20: 30.0 | S20: No | T20: 44955 | U20: https://img01.ztat.net/article/ZL100924.jpg | V20: =(Real_Sales[[#This Row],[Price_retail]]-Real_Sales[[#This Row],[Price_current]])/Real_Sales[[#This Row],[Price_retail]] -> 0.43047831 | W20: {=_xlfn.IFS(Real_Sales[[#This Row],[Discount]]=0%,"No Discount",Real_Sales[[#This Row],[Discount]]<=20%,"Light",Real_Sales[[#This Row],[Discount]]<=50%,"Moderate",Real_Sales[[#This Row],[Discount]]<=80%,"High", TRUE,"Very High")} -> Moderate | X20: =IF(Real_Sales[[#This Row],[Price_retail]]>$AC$3,"Premium","Average") -> Average | Y20: =IF(ISNUMBER(SEARCH("Basic",Real_Sales[[#This Row],[Product_name]])),"Yes","No") -> No | Z20: {=_xlfn.IFS(Real_Sales[[#This Row],[Price_retail]]<=15,1, Real_Sales[[#This Row],[Price_retail]]<=30,2, Real_Sales[[#This Row],[Price_retail]]<=50,3,Real_Sales[[#This Row],[Price_retail]]>50,4)} -> 1
A21: ZL100037 | B21: https://www.zalando.de/umbro-print-polo---light-grey-zl100037/ | C21: Umbro | D21: Print POLO - LIGHT GREY | E21: Men's T-Shirts & Polos | F21: Polo Shirts | G21: Slim Fit Polos | H21: Light Grey | I21: M | J21: 8.99 | K21: 5.17 | L21: SALE | M21: EUR | N21: 143 | O21: 3.4 | P21: 30.0 | S21: Yes | T21: 44955 | U21: https://img01.ztat.net/article/ZL100037.jpg | V21: =(Real_Sales[[#This Row],[Price_retail]]-Real_Sales[[#This Row],[Price_current]])/Real_Sales[[#This Row],[Price_retail]] -> 0.42491657 | W21: {=_xlfn.IFS(Real_Sales[[#This Row],[Discount]]=0%,"No Discount",Real_Sales[[#This Row],[Discount]]<=20%,"Light",Real_Sales[[#This Row],[Discount]]<=50%,"Moderate",Real_Sales[[#This Row],[Discount]]<=80%,"High", TRUE,"Very High")} -> Moderate | X21: =IF(Real_Sales[[#This Row],[Price_retail]]>$AC$3,"Premium","Average") -> Average | Y21: =IF(ISNUMBER(SEARCH("Basic",Real_Sales[[#This Row],[Product_name]])),"Yes","No") -> No | Z21: {=_xlfn.IFS(Real_Sales[[#This Row],[Price_retail]]<=15,1, Real_Sales[[#This Row],[Price_retail]]<=30,2, Real_Sales[[#This Row],[Price_retail]]<=50,3,Real_Sales[[#This Row],[Price_retail]]>50,4)} -> 1
A22: ZL100045 | B22: https://www.zalando.de/dickies-print-t-shirt---navy-zl100045/ | C22: Dickies | D22: Print T-SHIRT - NAVY | E22: Men's T-Shirts & Polos | F22: T-Shirts | G22: Long Sleeve T-Shirts | H22: Navy | I22: XS | J22: 8.99 | K22: 5.17 | L22: SALE | M22: EUR | N22: 548 | O22: 4.5 | P22: 28.0 | S22: Yes | T22: 44955 | U22: https://img01.ztat.net/article/ZL100045.jpg | V22: =(Real_Sales[[#This Row],[Price_retail]]-Real_Sales[[#This Row],[Price_current]])/Real_Sales[[#This Row],[Price_retail]] -> 0.42491657 | W22: {=_xlfn.IFS(Real_Sales[[#This Row],[Discount]]=0%,"No Discount",Real_Sales[[#This Row],[Discount]]<=20%,"Light",Real_Sales[[#This Row],[Discount]]<=50%,"Moderate",Real_Sales[[#This Row],[Discount]]<=80%,"High", TRUE,"Very High")} -> Moderate | X22: =IF(Real_Sales[[#This Row],[Price_retail]]>$AC$3,"Premium","Average") -> Average | Y22: =IF(ISNUMBER(SEARCH("Basic",Real_Sales[[#This Row],[Product_name]])),"Yes","No") -> No | Z22: {=_xlfn.IFS(Real_Sales[[#This Row],[Price_retail]]<=15,1, Real_Sales[[#This Row],[Price_retail]]<=30,2, Real_Sales[[#This Row],[Price_retail]]<=50,3,Real_Sales[[#This Row],[Price_retail]]>50,4)} -> 1
A23: ZL100404 | B23: https://www.zalando.de/columbia-essential-polo---mint-zl100404/ | C23: Columbia | D23: Essential POLO - MINT | E23: Men's T-Shirts & Polos | F23: Polo Shirts | G23: Slim Fit Polos | H23: Mint | I23: S | J23: 8.99 | K23: 5.26 | L23: SALE | M23: EUR | N23: 775 | O23: 3.4 | P23: 41.0 | S23: No | T23: 44955 | U23: https://img01.ztat.net/article/ZL100404.jpg | V23: =(Real_Sales[[#This Row],[Price_retail]]-Real_Sales[[#This Row],[Price_current]])/Real_Sales[[#This Row],[Price_retail]] -> 0.41490545 | W23: {=_xlfn.IFS(Real_Sales[[#This Row],[Discount]]=0%,"No Discount",Real_Sales[[#This Row],[Discount]]<=20%,"Light",Real_Sales[[#This Row],[Discount]]<=50%,"Moderate",Real_Sales[[#This Row],[Discount]]<=80%,"High", TRUE,"Very High")} -> Moderate | X23: =IF(Real_Sales[[#This Row],[Price_retail]]>$AC$3,"Premium","Average") -> Average | Y23: =IF(ISNUMBER(SEARCH("Basic",Real_Sales[[#This Row],[Product_name]])),"Yes","No") -> No | Z23: {=_xlfn.IFS(Real_Sales[[#This Row],[Price_retail]]<=15,1, Real_Sales[[#This Row],[Price_retail]]<=30,2, Real_Sales[[#This Row],[Price_retail]]<=50,3,Real_Sales[[#This Row],[Price_retail]]>50,4)} -> 1
A24: ZL100550 | B24: https://www.zalando.de/adidas-performance-print-polo---navy-zl100550/ | C24: Adidas Performance | D24: Print POLO - NAVY | E24: Men's T-Shirts & Polos | F24: Polo Shirts | G24: Basic Polos | H24: Navy | I24: XS | J24: 8.99 | K24: 5.3 | L24: SALE | M24: EUR | N24: 794 | O24: 3.9 | P24: 39.0 | S24: Yes | T24: 44955 | U24: https://img01.ztat.net/article/ZL100550.jpg | V24: =(Real_Sales[[#This Row],[Price_retail]]-Real_Sales[[#This Row],[Price_current]])/Real_Sales[[#This Row],[Price_retail]] -> 0.41045606 | W24: {=_xlfn.IFS(Real_Sales[[#This Row],[Discount]]=0%,"No Discount",Real_Sales[[#This Row],[Discount]]<=20%,"Light",Real_Sales[[#This Row],[Discount]]<=50%,"Moderate",Real_Sales[[#This Row],[Discount]]<=80%,"High", TRUE,"Very High")} -> Moderate | X24: =IF(Real_Sales[[#This Row],[Price_retail]]>$AC$3,"Premium","Average") -> Average | Y24: =IF(ISNUMBER(SEARCH("Basic",Real_Sales[[#This Row],[Product_name]])),"Yes","No") -> No | Z24: {=_xlfn.IFS(Real_Sales[[#This Row],[Price_retail]]<=15,1, Real_Sales[[#This Row],[Price_retail]]<=30,2, Real_Sales[[#This Row],[Price_retail]]<=50,3,Real_Sales[[#This Row],[Price_retail]]>50,4)} -> 1
A25: ZL100909 | B25: https://www.zalando.de/salomon-slim-fit-t-shirt---white-zl100909/ | C25: Salomon | D25: Slim Fit T-SHIRT - WHITE | E25: Men's T-Shirts & Polos | F25: T-Shirts | G25: Print T-Shirts | H25: White | I25: S | J25: 8.99 | K25: 5.34 | L25: SALE | M25: EUR | N25: 282 | O25: 4.1 | P25: 43.0 | S25: No | T25: 44955 | U25: https://img01.ztat.net/article/ZL100909.jpg | V25: =(Real_Sales[[#This Row],[Price_retail]]-Real_Sales[[#This Row],[Price_current]])/Real_Sales[[#This Row],[Price_retail]] -> 0.40600667 | W25: {=_xlfn.IFS(Real_Sales[[#This Row],[Discount]]=0%,"No Discount",Real_Sales[[#This Row],[Discount]]<=20%,"Light",Real_Sales[[#This Row],[Discount]]<=50%,"Moderate",Real_Sales[[#This Row],[Discount]]<=80%,"High", TRUE,"Very High")} -> Moderate | X25: =IF(Real_Sales[[#This Row],[Price_retail]]>$AC$3,"Premium","Average") -> Average | Y25: =IF(ISNUMBER(SEARCH("Basic",Real_Sales[[#This Row],[Product_name]])),"Yes","No") -> No | Z25: {=_xlfn.IFS(Real_Sales[[#This Row],[Price_retail]]<=15,1, Real_Sales[[#This Row],[Price_retail]]<=30,2, Real_Sales[[#This Row],[Price_retail]]<=50,3,Real_Sales[[#This Row],[Price_retail]]>50,4)} -> 1
A26: ZL100977 | B26: https://www.zalando.de/tommy-hilfiger-slim-fit-t-shirt---off-white-zl100977/ | C26: Tommy Hilfiger | D26: Slim Fit T-SHIRT - OFF WHITE | E26: Men's T-Shirts & Polos | F26: T-Shirts | G26: Print T-Shirts | H26: Off White | I26: S | J26: 8.99 | K26: 5.54 | L26: SALE | M26: EUR | N26: 451 | O26: 4.8 | P26: 42.0 | S26: Yes | T26: 44955 | U26: https://img01.ztat.net/article/ZL100977.jpg | V26: =(Real_Sales[[#This Row],[Price_retail]]-Real_Sales[[#This Row],[Price_current]])/Real_Sales[[#This Row],[Price_retail]] -> 0.38375973 | W26: {=_xlfn.IFS(Real_Sales[[#This Row],[Discount]]=0%,"No Discount",Real_Sales[[#This Row],[Discount]]<=20%,"Light",Real_Sales[[#This Row],[Discount]]<=50%,"Moderate",Real_Sales[[#This Row],[Discount]]<=80%,"High", TRUE,"Very High")} -> Moderate | X26: =IF(Real_Sales[[#This Row],[Price_retail]]>$AC$3,"Premium","Average") -> Average | Y26: =IF(ISNUMBER(SEARCH("Basic",Real_Sales[[#This Row],[Product_name]])),"Yes","No") -> No | Z26: {=_xlfn.IFS(Real_Sales[[#This Row],[Price_retail]]<=15,1, Real_Sales[[#This Row],[Price_retail]]<=30,2, Real_Sales[[#This Row],[Price_retail]]<=50,3,Real_Sales[[#This Row],[Price_retail]]>50,4)} -> 1
A27: ZL100085 | B27: https://www.zalando.de/new-look-print-t-shirt---royal-blue-zl100085/ | C27: New Look | D27: Print T-SHIRT - ROYAL BLUE | E27: Men's T-Shirts & Polos | F27: T-Shirts | G27: Slim Fit T-Shirts | H27: Royal Blue | I27: XS | J27: 8.99 | K27: 5.64 | L27: SALE | M27: EUR | N27: 244 | O27: 4.0 | P27: 31.0 | S27: No | T27: 44955 | U27: https://img01.ztat.net/article/ZL100085.jpg | V27: =(Real_Sales[[#This Row],[Price_retail]]-Real_Sales[[#This Row],[Price_current]])/Real_Sales[[#This Row],[Price_retail]] -> 0.37263626 | W27: {=_xlfn.IFS(Real_Sales[[#This Row],[Discount]]=0%,"No Discount",Real_Sales[[#This Row],[Discount]]<=20%,"Light",Real_Sales[[#This Row],[Discount]]<=50%,"Moderate",Real_Sales[[#This Row],[Discount]]<=80%,"High", TRUE,"Very High")} -> Moderate | X27: =IF(Real_Sales[[#This Row],[Price_retail]]>$AC$3,"Premium","Average") -> Average | Y27: =IF(ISNUMBER(SEARCH("Basic",Real_Sales[[#This Row],[Product_name]])),"Yes","No") -> No | Z27: {=_xlfn.IFS(Real_Sales[[#This Row],[Price_retail]]<=15,1, Real_Sales[[#This Row],[Price_retail]]<=30,2, Real_Sales[[#This Row],[Price_retail]]<=50,3,Real_Sales[[#This Row],[Price_retail]]>50,4)} -> 1
A28: ZL100549 | B28: https://www.zalando.de/craft-sportswear-slim-fit-polo---anthracite-zl100549/ | C28: Craft | D28: Slim Fit POLO - ANTHRACITE | E28: Men's T-Shirts & Polos | F28: Polo Shirts | G28: Pique Polos | H28: Anthracite | J28: 8.99 | K28: 5.65 | L28: SALE | M28: EUR | N28: 788 | O28: 4.5 | P28: 33.0 | S28: No | T28: 44955 | U28: https://img01.ztat.net/article/ZL100549.jpg | V28: =(Real_Sales[[#This Row],[Price_retail]]-Real_Sales[[#This Row],[Price_current]])/Real_Sales[[#This Row],[Price_retail]] -> 0.37152392 | W28: {=_xlfn.IFS(Real_Sales[[#This Row],[Discount]]=0%,"No Discount",Real_Sales[[#This Row],[Discount]]<=20%,"Light",Real_Sales[[#This Row],[Discount]]<=50%,"Moderate",Real_Sales[[#This Row],[Discount]]<=80%,"High", TRUE,"Very High")} -> Moderate | X28: =IF(Real_Sales[[#This Row],[Price_retail]]>$AC$3,"Premium","Average") -> Average | Y28: =IF(ISNUMBER(SEARCH("Basic",Real_Sales[[#This Row],[Product_name]])),"Yes","No") -> No | Z28: {=_xlfn.IFS(Real_Sales[[#This Row],[Price_retail]]<=15,1, Real_Sales[[#This Row],[Price_retail]]<=30,2, Real_Sales[[#This Row],[Price_retail]]<=50,3,Real_Sales[[#This Row],[Price_retail]]>50,4)} -> 1
A29: ZL100964 | B29: https://www.zalando.de/nudie-jeans-slim-fit-polo---off-white-zl100964/ | C29: Nudie Jeans | D29: Slim Fit POLO - OFF WHITE | E29: Men's T-Shirts & Polos | F29: Polo Shirts | G29: Basic Polos | H29: Off White | I29: S | J29: 8.99 | K29: 5.7 | L29: SALE | M29: EUR | N29: 129 | O29: 0 | P29: 46.0 | S29: Yes | T29: 44955 | U29: https://img01.ztat.net/article/ZL100964.jpg | V29: =(Real_Sales[[#This Row],[Price_retail]]-Real_Sales[[#This Row],[Price_current]])/Real_Sales[[#This Row],[Price_retail]] -> 0.36596218 | W29: {=_xlfn.IFS(Real_Sales[[#This Row],[Discount]]=0%,"No Discount",Real_Sales[[#This Row],[Discount]]<=20%,"Light",Real_Sales[[#This Row],[Discount]]<=50%,"Moderate",Real_Sales[[#This Row],[Discount]]<=80%,"High", TRUE,"Very High")} -> Moderate | X29: =IF(Real_Sales[[#This Row],[Price_retail]]>$AC$3,"Premium","Average") -> Average | Y29: =IF(ISNUMBER(SEARCH("Basic",Real_Sales[[#This Row],[Product_name]])),"Yes","No") -> No | Z29: {=_xlfn.IFS(Real_Sales[[#This Row],[Price_retail]]<=15,1, Real_Sales[[#This Row],[Price_retail]]<=30,2, Real_Sales[[#This Row],[Price_retail]]<=50,3,Real_Sales[[#This Row],[Price_retail]]>50,4)} -> 1
A30: ZL100202 | B30: https://www.zalando.de/olymp-slim-fit-polo---rust-zl100202/ | C30: Olymp | D30: Slim Fit POLO - RUST | E30: Men's T-Shirts & Polos | F30: Polo Shirts | G30: Basic Polos | H30: Rust | I30: S | J30: 8.99 | K30: 5.81 | L30: SALE | M30: EUR | N30: 795 | O30: 4.5 | P30: 32.0 | S30: No | T30: 44955 | U30: https://img01.ztat.net/article/ZL100202.jpg | V30: =(Real_Sales[[#This Row],[Price_retail]]-Real_Sales[[#This Row],[Price_current]])/Real_Sales[[#This Row],[Price_retail]] -> 0.35372636 | W30: {=_xlfn.IFS(Real_Sales[[#This Row],[Discount]]=0%,"No Discount",Real_Sales[[#This Row],[Discount]]<=20%,"Light",Real_Sales[[#This Row],[Discount]]<=50%,"Moderate",Real_Sales[[#This Row],[Discount]]<=80%,"High", TRUE,"Very High")} -> Moderate | X30: =IF(Real_Sales[[#This Row],[Price_retail]]>$AC$3,"Premium","Average") -> Average | Y30: =IF(ISNUMBER(SEARCH("Basic",Real_Sales[[#This Row],[Product_name]])),"Yes","No") -> No | Z30: {=_xlfn.IFS(Real_Sales[[#This Row],[Price_retail]]<=15,1, Real_Sales[[#This Row],[Price_retail]]<=30,2, Real_Sales[[#This Row],[Price_retail]]<=50,3,Real_Sales[[#This Row],[Price_retail]]>50,4)} -> 1
A31: ZL100066 | B31: https://www.zalando.de/nike-essential-polo---anthracite-zl100066/ | C31: Nike | D31: Essential POLO - ANTHRACITE | E31: Men's T-Shirts & Polos | F31: Polo Shirts | G31: Pique Polos | H31: Anthracite | I31: M | J31: 8.99 | K31: 5.83 | L31: SALE | M31: EUR | N31: 533 | O31: 3.6 | P31: 39.0 | S31: Yes | T31: 44955 | U31: https://img01.ztat.net/article/ZL100066.jpg | V31: =(Real_Sales[[#This Row],[Price_retail]]-Real_Sales[[#This Row],[Price_current]])/Real_Sales[[#This Row],[Price_retail]] -> 0.35150167 | W31: {=_xlfn.IFS(Real_Sales[[#This Row],[Discount]]=0%,"No Discount",Real_Sales[[#This Row],[Discount]]<=20%,"Light",Real_Sales[[#This Row],[Discount]]<=50%,"Moderate",Real_Sales[[#This Row],[Discount]]<=80%,"High", TRUE,"Very High")} -> Moderate | X31: =IF(Real_Sales[[#This Row],[Price_retail]]>$AC$3,"Premium","Average") -> Average | Y31: =IF(ISNUMBER(SEARCH("Basic",Real_Sales[[#This Row],[Product_name]])),"Yes","No") -> No | Z31: {=_xlfn.IFS(Real_Sales[[#This Row],[Price_retail]]<=15,1, Real_Sales[[#This Row],[Price_retail]]<=30,2, Real_Sales[[#This Row],[Price_retail]]<=50,3,Real_Sales[[#This Row],[Price_retail]]>50,4)} -> 1
A32: ZL100890 | B32: https://www.zalando.de/nike-regular-fit-t-shirt---off-white-zl100890/ | C32: Nike | D32: Regular Fit T-SHIRT - OFF WHITE | E32: Men's T-Shirts & Polos | F32: T-Shirts | G32: Slim Fit T-Shirts | H32: Off White | I32: S | J32: 8.99 | K32: 5.83 | L32: SALE | M32: EUR | N32: 933 | O32: 4.8 | P32: 0 | S32: No | T32: 44955 | U32: https://img01.ztat.net/article/ZL100890.jpg | V32: =(Real_Sales[[#This Row],[Price_retail]]-Real_Sales[[#This Row],[Price_current]])/Real_Sales[[#This Row],[Price_retail]] -> 0.35150167 | W32: {=_xlfn.IFS(Real_Sales[[#This Row],[Discount]]=0%,"No Discount",Real_Sales[[#This Row],[Discount]]<=20%,"Light",Real_Sales[[#This Row],[Discount]]<=50%,"Moderate",Real_Sales[[#This Row],[Discount]]<=80%,"High", TRUE,"Very High")} -> Moderate | X32: =IF(Real_Sales[[#This Row],[Price_retail]]>$AC$3,"Premium","Average") -> Average | Y32: =IF(ISNUMBER(SEARCH("Basic",Real_Sales[[#This Row],[Product_name]])),"Yes","No") -> No | Z32: {=_xlfn.IFS(Real_Sales[[#This Row],[Price_retail]]<=15,1, Real_Sales[[#This Row],[Price_retail]]<=30,2, Real_Sales[[#This Row],[Price_retail]]<=50,3,Real_Sales[[#This Row],[Price_retail]]>50,4)} -> 1
A33: ZL100688 | B33: https://www.zalando.de/jack-jones-junior-print-t-shirt---white-zl100688/ | C33: Jack & Jones Junior | D33: Print T-SHIRT - WHITE | E33: Men's T-Shirts & Polos | F33: T-Shirts | G33: Long Sleeve T-Shirts | H33: White | I33: XS | J33: 8.99 | K33: 5.86 | L33: SALE | M33: EUR | N33: 565 | O33: 3.2 | P33: 38.0 | S33: Yes | T33: 44955 | U33: https://img01.ztat.net/article/ZL100688.jpg | V33: =(Real_Sales[[#This Row],[Price_retail]]-Real_Sales[[#This Row],[Price_current]])/Real_Sales[[#This Row],[Price_retail]] -> 0.34816463 | W33: {=_xlfn.IFS(Real_Sales[[#This Row],[Discount]]=0%,"No Discount",Real_Sales[[#This Row],[Discount]]<=20%,"Light",Real_Sales[[#This Row],[Discount]]<=50%,"Moderate",Real_Sales[[#This Row],[Discount]]<=80%,"High", TRUE,"Very High")} -> Moderate | X33: =IF(Real_Sales[[#This Row],[Price_retail]]>$AC$3,"Premium","Average") -> Average | Y33: =IF(ISNUMBER(SEARCH("Basic",Real_Sales[[#This Row],[Product_name]])),"Yes","No") -> No | Z33: {=_xlfn.IFS(Real_Sales[[#This Row],[Price_retail]]<=15,1, Real_Sales[[#This Row],[Price_retail]]<=30,2, Real_Sales[[#This Row],[Price_retail]]<=50,3,Real_Sales[[#This Row],[Price_retail]]>50,4)} -> 1
A34: ZL100908 | B34: https://www.zalando.de/digel-print-t-shirt---olive-zl100908/ | C34: Digel | D34: Print T-SHIRT - OLIVE | E34: Men's T-Shirts & Polos | F34: T-Shirts | G34: Print T-Shirts | H34: Olive | I34: S | J34: 8.99 | K34: 5.86 | L34: SALE | M34: EUR | N34: 883 | O34: 4.5 | P34: 39.0 | S34: Yes | T34: 44955 | U34: https://img01.ztat.net/article/ZL100908.jpg | V34: =(Real_Sales[[#This Row],[Price_retail]]-Real_Sales[[#This Row],[Price_current]])/Real_Sales[[#This Row],[Price_retail]] -> 0.34816463 | W34: {=_xlfn.IFS(Real_Sales[[#This Row],[Discount]]=0%,"No Discount",Real_Sales[[#This Row],[Discount]]<=20%,"Light",Real_Sales[[#This Row],[Discount]]<=50%,"Moderate",Real_Sales[[#This Row],[Discount]]<=80%,"High", TRUE,"Very High")} -> Moderate | X34: =IF(Real_Sales[[#This Row],[Price_retail]]>$AC$3,"Premium","Average") -> Average | Y34: =IF(ISNUMBER(SEARCH("Basic",Real_Sales[[#This Row],[Product_name]])),"Yes","No") -> No | Z34: {=_xlfn.IFS(Real_Sales[[#This Row],[Price_retail]]<=15,1, Real_Sales[[#This Row],[Price_retail]]<=30,2, Real_Sales[[#This Row],[Price_retail]]<=50,3,Real_Sales[[#This Row],[Price_retail]]>50,4)} -> 1
A35: ZL100350 | B35: https://www.zalando.de/hollister-co.-essential-t-shirt---mint-zl100350/ | C35: Hollister Co. | D35: Essential T-SHIRT - MINT | E35: Men's T-Shirts & Polos | F35: T-Shirts | G35: Print T-Shirts | H35: Mint | I35: M | J35: 8.99 | K35: 5.89 | L35: SALE | M35: EUR | N35: 269 | O35: N/A | P35: 31.0 | S35: Yes | T35: 44955 | U35: https://img01.ztat.net/article/ZL100350.jpg | V35: =(Real_Sales[[#This Row],[Price_retail]]-Real_Sales[[#This Row],[Price_current]])/Real_Sales[[#This Row],[Price_retail]] -> 0.34482759 | W35: {=_xlfn.IFS(Real_Sales[[#This Row],[Discount]]=0%,"No Discount",Real_Sales[[#This Row],[Discount]]<=20%,"Light",Real_Sales[[#This Row],[Discount]]<=50%,"Moderate",Real_Sales[[#This Row],[Discount]]<=80%,"High", TRUE,"Very High")} -> Moderate | X35: =IF(Real_Sales[[#This Row],[Price_retail]]>$AC$3,"Premium","Average") -> Average | Y35: =IF(ISNUMBER(SEARCH("Basic",Real_Sales[[#This Row],[Product_name]])),"Yes","No") -> No | Z35: {=_xlfn.IFS(Real_Sales[[#This Row],[Price_retail]]<=15,1, Real_Sales[[#This Row],[Price_retail]]<=30,2, Real_Sales[[#This Row],[Price_retail]]<=50,3,Real_Sales[[#This Row],[Price_retail]]>50,4)} -> 1
A36: ZL100017 | B36: https://www.zalando.de/cleptomanicx-regular-fit-t-shirt---black-zl100017/ | C36: Cleptomanicx | D36: Regular Fit T-SHIRT - BLACK | E36: Men's T-Shirts & Polos | F36: T-Shirts | G36: Slim Fit T-Shirts | H36: Black | I36: M | J36: 8.99 | K36: 5.93 | L36: SALE | M36: EUR | N36: 435 | O36: 0 | P36: 38.0 | S36: Yes | T36: 44955 | U36: https://img01.ztat.net/article/ZL100017.jpg | V36: =(Real_Sales[[#This Row],[Price_retail]]-Real_Sales[[#This Row],[Price_current]])/Real_Sales[[#This Row],[Price_retail]] -> 0.3403782 | W36: {=_xlfn.IFS(Real_Sales[[#This Row],[Discount]]=0%,"No Discount",Real_Sales[[#This Row],[Discount]]<=20%,"Light",Real_Sales[[#This Row],[Discount]]<=50%,"Moderate",Real_Sales[[#This Row],[Discount]]<=80%,"High", TRUE,"Very High")} -> Moderate | X36: =IF(Real_Sales[[#This Row],[Price_retail]]>$AC$3,"Premium","Average") -> Average | Y36: =IF(ISNUMBER(SEARCH("Basic",Real_Sales[[#This Row],[Product_name]])),"Yes","No") -> No | Z36: {=_xlfn.IFS(Real_Sales[[#This Row],[Price_retail]]<=15,1, Real_Sales[[#This Row],[Price_retail]]<=30,2, Real_Sales[[#This Row],[Price_retail]]<=50,3,Real_Sales[[#This Row],[Price_retail]]>50,4)} -> 1
A37: ZL100950 | B37: https://www.zalando.de/napapijri-basic-t-shirt---dark-green-zl100950/ | C37: Napapijri | D37: Basic T-SHIRT - DARK GREEN | E37: Men's T-Shirts & Polos | F37: T-Shirts | G37: Slim Fit T-Shirts | H37: Dark Green | I37: S | J37: 8.99 | K37: 6 | L37: SALE | M37: EUR | N37: 984 | O37: 3.1 | P37: 32.0 | S37: Yes | T37: 44955 | U37: https://img01.ztat.net/article/ZL100950.jpg | V37: =(Real_Sales[[#This Row],[Price_retail]]-Real_Sales[[#This Row],[Price_current]])/Real_Sales[[#This Row],[Price_retail]] -> 0.33259177 | W37: {=_xlfn.IFS(Real_Sales[[#This Row],[Discount]]=0%,"No Discount",Real_Sales[[#This Row],[Discount]]<=20%,"Light",Real_Sales[[#This Row],[Discount]]<=50%,"Moderate",Real_Sales[[#This Row],[Discount]]<=80%,"High", TRUE,"Very High")} -> Moderate | X37: =IF(Real_Sales[[#This Row],[Price_retail]]>$AC$3,"Premium","Average") -> Average | Y37: =IF(ISNUMBER(SEARCH("Basic",Real_Sales[[#This Row],[Product_name]])),"Yes","No") -> Yes | Z37: {=_xlfn.IFS(Real_Sales[[#This Row],[Price_retail]]<=15,1, Real_Sales[[#This Row],[Price_retail]]<=30,2, Real_Sales[[#This Row],[Price_retail]]<=50,3,Real_Sales[[#This Row],[Price_retail]]>50,4)} -> 1
A38: ZL100224 | B38: https://www.zalando.de/produkt-slim-fit-t-shirt---grey-melange-zl100224/ | C38: Produkt | D38: Slim Fit T-SHIRT - GREY MELANGE | E38: Men's T-Shirts & Polos | F38: T-Shirts | G38: Basic T-Shirts | H38: Grey Melange | I38: XS | J38: 8.99 | K38: 6.02 | L38: SALE | M38: EUR | N38: 400 | O38: 4.7 | P38: 29.0 | S38: No | T38: 44955 | U38: https://img01.ztat.net/article/ZL100224.jpg | V38: =(Real_Sales[[#This Row],[Price_retail]]-Real_Sales[[#This Row],[Price_current]])/Real_Sales[[#This Row],[Price_retail]] -> 0.33036707 | W38: {=_xlfn.IFS(Real_Sales[[#This Row],[Discount]]=0%,"No Discount",Real_Sales[[#This Row],[Discount]]<=20%,"Light",Real_Sales[[#This Row],[Discount]]<=50%,"Moderate",Real_Sales[[#This Row],[Discount]]<=80%,"High", TRUE,"Very High")} -> Moderate | X38: =IF(Real_Sales[[#This Row],[Price_retail]]>$AC$3,"Premium","Average") -> Average | Y38: =IF(ISNUMBER(SEARCH("Basic",Real_Sales[[#This Row],[Product_name]])),"Yes","No") -> No | Z38: {=_xlfn.IFS(Real_Sales[[#This Row],[Price_retail]]<=15,1, Real_Sales[[#This Row],[Price_retail]]<=30,2, Real_Sales[[#This Row],[Price_retail]]<=50,3,Real_Sales[[#This Row],[Price_retail]]>50,4)} -> 1
A39: ZL100035 | B39: https://www.zalando.de/kappa-print-t-shirt---royal-blue-zl100035/ | C39: Kappa | D39: Print T-SHIRT - ROYAL BLUE | E39: Men's T-Shirts & Polos | F39: T-Shirts | G39: Slim Fit T-Shirts | H39: Royal Blue | I39: XS | J39: 8.99 | K39: 6.41 | L39: SALE | M39: EUR | N39: 922 | O39: 4.6 | P39: 33.0 | S39: Yes | T39: 44955 | U39: https://img01.ztat.net/article/ZL100035.jpg | V39: =(Real_Sales[[#This Row],[Price_retail]]-Real_Sales[[#This Row],[Price_current]])/Real_Sales[[#This Row],[Price_retail]] -> 0.28698554 | W39: {=_xlfn.IFS(Real_Sales[[#This Row],[Discount]]=0%,"No Discount",Real_Sales[[#This Row],[Discount]]<=20%,"Light",Real_Sales[[#This Row],[Discount]]<=50%,"Moderate",Real_Sales[[#This Row],[Discount]]<=80%,"High", TRUE,"Very High")} -> Moderate | X39: =IF(Real_Sales[[#This Row],[Price_retail]]>$AC$3,"Premium","Average") -> Average | Y39: =IF(ISNUMBER(SEARCH("Basic",Real_Sales[[#This Row],[Product_name]])),"Yes","No") -> No | Z39: {=_xlfn.IFS(Real_Sales[[#This Row],[Price_retail]]<=15,1, Real_Sales[[#This Row],[Price_retail]]<=30,2, Real_Sales[[#This Row],[Price_retail]]<=50,3,Real_Sales[[#This Row],[Price_retail]]>50,4)} -> 1
A40: ZL100079 | B40: https://www.zalando.de/produkt-slim-fit-t-shirt---rust-zl100079/ | C40: Produkt | D40: Slim Fit T-SHIRT - RUST | E40: Men's T-Shirts & Polos | F40: T-Shirts | G40: Slim Fit T-Shirts | H40: Rust | I40: S | J40: 8.99 | K40: 6.41 | L40: SALE | M40: EUR | N40: 671 | O40: 0 | P40: 33.0 | S40: No | T40: 44955 | U40: https://img01.ztat.net/article/ZL100079.jpg | V40: =(Real_Sales[[#This Row],[Price_retail]]-Real_Sales[[#This Row],[Price_current]])/Real_Sales[[#This Row],[Price_retail]] -> 0.28698554 | W40: {=_xlfn.IFS(Real_Sales[[#This Row],[Discount]]=0%,"No Discount",Real_Sales[[#This Row],[Discount]]<=20%,"Light",Real_Sales[[#This Row],[Discount]]<=50%,"Moderate",Real_Sales[[#This Row],[Discount]]<=80%,"High", TRUE,"Very High")} -> Moderate | X40: =IF(Real_Sales[[#This Row],[Price_retail]]>$AC$3,"Premium","Average") -> Average | Y40: =IF(ISNUMBER(SEARCH("Basic",Real_Sales[[#This Row],[Product_name]])),"Yes","No") -> No | Z40: {=_xlfn.IFS(Real_Sales[[#This Row],[Price_retail]]<=15,1, Real_Sales[[#This Row],[Price_retail]]<=30,2, Real_Sales[[#This Row],[Price_retail]]<=50,3,Real_Sales[[#This Row],[Price_retail]]>50,4)} -> 1
...

Sheet Row
A1: Sku | B1: Product_url | C1: Brand | D1: Product_name | E1: Category | F1: Subcategory | G1: Subsubcategory | H1: Color | I1: Size_range | J1: Price_retail | K1: Price_current | L1: Price_label | M1: Currency | N1: Sort_by_ranking | O1: Rating | P1: Reviews_count | Q1: Promotion | R1: Sku_variant | S1: In_stock | T1: Scan_date | U1: Image_url | V1: Discount | W1: Discount Level
A2: ZL100000 | B2: https://www.zalando.de/petrol-industries-slim-fit-polo---red-zl100000/ | C2: Petrol Industries | D2: Slim Fit POLO - RED | E2: Men's T-Shirts & Polos | F2: Polo Shirts | G2: Pique Polos | H2: Red | J2: 99.99 | K2: 42.31 | L2: SALE | M2: EUR | N2: 652 | O2: 5.0 | P2: 47.0 | S2: No | T2: 44955 | U2: https://img01.ztat.net/article/ZL100000.jpg | V2: =(Sales[[#This Row],[Price_retail]]-Sales[[#This Row],[Price_current]])/Sales[[#This Row],[Price_retail]] -> 0.57685769 | W2: {=_xlfn.IFS(Sales[[#This Row],[Discount]]=0%,"No Discount",Sales[[#This Row],[Discount]]<=20%,"Light",Sales[[#This Row],[Discount]]<=50%,"Moderate",Sales[[#This Row],[Discount]]<=80%,"High", TRUE,"Very High")} -> High
A3: ZL100001 | B3: https://www.zalando.de/only-and-sons-denim-print-t-shirt---rust-zl100001/ | C3: Only & Sons | D3: Print T-SHIRT - RUST | E3: Men's T-Shirts & Polos | F3: T-Shirts | G3: Long Sleeve T-Shirts | H3: Rust | I3: S | J3: 22.03 | K3: 22.03 | L3: Regular Price | M3: EUR | N3: 316 | O3: 3.8 | P3: 0 | S3: Yes | T3: 44955 | U3: https://img01.ztat.net/article/ZL100001.jpg | V3: =(Sales[[#This Row],[Price_retail]]-Sales[[#This Row],[Price_current]])/Sales[[#This Row],[Price_retail]] -> 0 | W3: {=_xlfn.IFS(Sales[[#This Row],[Discount]]=0%,"No Discount",Sales[[#This Row],[Discount]]<=20%,"Light",Sales[[#This Row],[Discount]]<=50%,"Moderate",Sales[[#This Row],[Discount]]<=80%,"High", TRUE,"Very High")} -> No Discount
A4: ZL100002 | B4: https://www.zalando.de/anerkjendt-essential-t-shirt---grey-melange-zl100002/ | C4: Anerkjendt | D4: Essential T-SHIRT - GREY MELANGE | E4: Men's T-Shirts & Polos | F4: T-Shirts | G4: Slim Fit T-Shirts | H4: Grey Melange | I4: XS | J4: 26.38 | K4: 26.38 | L4: Regular Price | M4: EUR | N4: 990 | O4: 3.1 | P4: 29.0 | S4: Yes | T4: 44955 | U4: https://img01.ztat.net/article/ZL100002.jpg | V4: =(Sales[[#This Row],[Price_retail]]-Sales[[#This Row],[Price_current]])/Sales[[#This Row],[Price_retail]] -> 0 | W4: {=_xlfn.IFS(Sales[[#This Row],[Discount]]=0%,"No Discount",Sales[[#This Row],[Discount]]<=20%,"Light",Sales[[#This Row],[Discount]]<=50%,"Moderate",Sales[[#This Row],[Discount]]<=80%,"High", TRUE,"Very High")} -> No Discount
A5: ZL100003 | B5: https://www.zalando.de/adidas-performance-regular-fit-t-shirt---khaki-zl100003/ | C5: Adidas Performance | D5: Regular Fit T-SHIRT - KHAKI | E5: Men's T-Shirts & Polos | F5: T-Shirts | G5: Slim Fit T-Shirts | H5: Khaki | I5: M | J5: 21.05 | K5: 12.67 | L5: SALE | M5: EUR | N5: 473 | O5: 3.9 | P5: 31.0 | S5: Yes | T5: 44955 | U5: https://img01.ztat.net/article/ZL100003.jpg | V5: =(Sales[[#This Row],[Price_retail]]-Sales[[#This Row],[Price_current]])/Sales[[#This Row],[Price_retail]] -> 0.39809976 | W5: {=_xlfn.IFS(Sales[[#This Row],[Discount]]=0%,"No Discount",Sales[[#This Row],[Discount]]<=20%,"Light",Sales[[#This Row],[Discount]]<=50%,"Moderate",Sales[[#This Row],[Discount]]<=80%,"High", TRUE,"Very High")} -> Moderate
A6: ZL100288 | B6: https://www.zalando.de/lacoste-essential-polo---rust-zl100004/ | C6: Lacoste | D6: Essential POLO - RUST | E6: Men's T-Shirts & Polos | F6: Polo Shirts | G6: Pique Polos | H6: Rust | I6: XS | J6: 32.81 | K6: 13.19 | L6: SALE | M6: EUR | N6: 535 | O6: 3.3 | P6: 34.0 | S6: Yes | T6: 44955 | U6: https://img01.ztat.net/article/ZL100004.jpg | V6: =(Sales[[#This Row],[Price_retail]]-Sales[[#This Row],[Price_current]])/Sales[[#This Row],[Price_retail]] -> 0.59798842 | W6: {=_xlfn.IFS(Sales[[#This Row],[Discount]]=0%,"No Discount",Sales[[#This Row],[Discount]]<=20%,"Light",Sales[[#This Row],[Discount]]<=50%,"Moderate",Sales[[#This Row],[Discount]]<=80%,"High", TRUE,"Very High")} -> High
